<?xml version="1.0" encoding="utf-8" ?>
<!-- =================================================================================== -->
<!-- |    This document was autogenerated by xacro from /home/robotica/robotica_ws/src/esercizio3_pkg/robot/fanuc.xacro | -->
<!-- |    EDITING THIS FILE BY HAND IS NOT RECOMMENDED                                 | -->
<!-- =================================================================================== -->
<!-- 
    This URDF uses the Denavit-Hartenberg (DH) conventions to place the reference frames of the joints.
    It uses offsets to correctly place the visual and collision meshes. The Fanuc meshes are
    generated such that their reference frames' origins are always placed in a center of rotation.
    This allows to offset the visual and collision meshes by using only the displacements in the
    mechanical drawing, without the need for manual (and error-prone) adjustements.
-->
<robot name="fanuc">
    <!-- ******************** Used for fixing robot to Gazebo 'base_link' ********************-->
    <link name="world" />
    <joint name="virtual_joint" type="fixed">
        <parent link="world" />
        <child link="base_link" />
    </joint>
    <!--************************************************BASE_LINK********************************************-->
    <link name="base_link">
        <!--link properties-->
        <visual>
            <origin rpy="0 0 0" xyz="0 0 0" />
            <geometry>
                <mesh filename="package://esercizio3_pkg/meshes/visual/link_0.dae" />
            </geometry>
            <material name="" />
        </visual>
        <collision>
            <origin rpy="0 0 0" xyz="0 0 0" />
            <geometry>
                <mesh filename="package://esercizio3_pkg/meshes/collision/link_0.stl" />
            </geometry>
        </collision>
        
<inertial>
            <mass value="0.1" />
            <inertia ixx="0.03" iyy="0.03" izz="0.03" ixy="0.0" ixz="0.0" iyz="0.0" />
        </inertial>

    </link>
    <!--************************************************LINK 1********************************************-->
    <link name="link1">
        <!--Link properties-->
        <visual>
            <origin rpy="0 0 0" xyz="0 0 -0.45" />
            <geometry>
                <mesh filename="package://esercizio3_pkg/meshes/visual/link_1.dae" />
            </geometry>
            <material name="" />
        </visual>
        <collision>
            <origin rpy="0 0 0" xyz="0 0 -0.45" />
            <geometry>
                <mesh filename="package://esercizio3_pkg/meshes/collision/link_1.stl" />
            </geometry>
        </collision>
        
<inertial>
            <mass value="0.1" />
            <inertia ixx="0.03" iyy="0.03" izz="0.03" ixy="0.0" ixz="0.0" iyz="0.0" />
        </inertial>

    </link>
    <joint name="joint1" type="revolute">
        <!--Joint properties-->
        <origin rpy="0 0 0" xyz="0 0 0.45" />
        <parent link="base_link" />
        <child link="link1" />
        <axis xyz="0 0 1" />
        <limit effort="12" lower="-3.14" upper="3.14" velocity="4.54" />
        <dynamics damping="10.0" friction="50.0" />
    </joint>
    <!--************************************************LINK 2********************************************-->
    <link name="link2">
        <!--Link properties-->
        <visual>
            <origin rpy="1.57 0 1.57" xyz="-0.51 -0.15 0.15" />
            <geometry>
                <mesh filename="package://esercizio3_pkg/meshes/visual/link_2.dae" />
            </geometry>
            <material name="" />
        </visual>
        <collision>
            <origin rpy="1.57 0 1.57" xyz="-0.51 -0.15 0.15" />
            <geometry>
                <mesh filename="package://esercizio3_pkg/meshes/collision/link_2.stl" />
            </geometry>
        </collision>
        
<inertial>
            <mass value="0.1" />
            <inertia ixx="0.03" iyy="0.03" izz="0.03" ixy="0.0" ixz="0.0" iyz="0.0" />
        </inertial>

    </link>
    <joint name="joint2" type="revolute">
        <!--Joint properties-->
        <origin rpy="-1.57 -1.57 0" xyz="0.15 -0.15 0.08" />
        <parent link="link1" />
        <child link="link2" />
        <axis xyz="0 0 1" />
        <limit effort="12" lower="-2.18" upper="2.18" velocity="4.89" />
        <dynamics damping="10.0" friction="50.0" />
    </joint>
    <!--************************************************LINK 3********************************************-->
    <link name="link3">
        <!--Link properties-->
        <visual>
            <origin rpy="-1.57 -3.14 -3.14" xyz="-0.15 1.31 0.15" />
            <geometry>
                <mesh filename="package://esercizio3_pkg/meshes/visual/link_3.dae" />
            </geometry>
            <material name="" />
        </visual>
        <collision>
            <origin rpy="-1.57 -3.14 -3.14" xyz="-0.15 1.31 0.15" />
            <geometry>
                <mesh filename="package://esercizio3_pkg/meshes/collision/link_3.stl" />
            </geometry>
        </collision>
        
<inertial>
            <mass value="0.1" />
            <inertia ixx="0.03" iyy="0.03" izz="0.03" ixy="0.0" ixz="0.0" iyz="0.0" />
        </inertial>

    </link>
    <joint name="joint3" type="revolute">
        <!--Joint properties-->
        <origin rpy="0 0 0" xyz="0.8 0 0" />
        <parent link="link2" />
        <child link="link3" />
        <axis xyz="0 0 1" />
        <limit effort="12" lower="-2.67" upper="2.67" velocity="5.50" />
        <dynamics damping="10.0" friction="50.0" />
    </joint>
    <!--************************************************LINK 4********************************************-->
    <link name="link4">
        <!--Link properties-->
        <visual>
            <origin rpy="-1.57 0 -1.57" xyz="-1.46 1.0 0.1" />
            <geometry>
                <mesh filename="package://esercizio3_pkg/meshes/visual/link_4.dae" />
            </geometry>
            <material name="" />
        </visual>
        <collision>
            <origin rpy="-1.57 0 -1.57" xyz="-1.46 1.0 0.1 " />
            <geometry>
                <mesh filename="package://esercizio3_pkg/meshes/collision/link_4.stl" />
            </geometry>
        </collision>
        
<inertial>
            <mass value="0.1" />
            <inertia ixx="0.03" iyy="0.03" izz="0.03" ixy="0.0" ixz="0.0" iyz="0.0" />
        </inertial>

    </link>
    <joint name="joint4" type="revolute">
        <!--Joint properties-->
        <origin rpy="1.57 0 1.57" xyz="0.2 -0.15 0.15" />
        <parent link="link3" />
        <child link="link4" />
        <axis xyz="0 0 1" />
        <limit effort="11.7" lower="-3.165" upper="3.165" velocity="7.5" />
        <dynamics damping="10.0" friction="50.0" />
    </joint>
    <!--************************************************LINK 5********************************************-->
    <link name="link5">
        <!--Link properties-->
        <visual>
            <origin rpy="1.57 1.57 1.57" xyz="-1.46 0 0.93" />
            <geometry>
                <mesh filename="package://esercizio3_pkg/meshes/visual/link_5.dae" />
            </geometry>
            <material name="" />
        </visual>
        <collision>
            <origin rpy="1.57 1.57 1.57" xyz="-1.46 0 0.93" />
            <geometry>
                <mesh filename="package://esercizio3_pkg/meshes/collision/link_5.stl" />
            </geometry>
        </collision>
        
<inertial>
            <mass value="0.1" />
            <inertia ixx="0.03" iyy="0.03" izz="0.03" ixy="0.0" ixz="0.0" iyz="0.0" />
        </inertial>

    </link>
    <joint name="joint5" type="revolute">
        <!--Joint properties-->
        <origin rpy="1.57 0 0" xyz="0 0.64 0.1" />
        <parent link="link4" />
        <child link="link5" />
        <axis xyz="0 0 1" />
        <limit effort="11.7" lower="-3.32" upper="3.32" velocity="7.50" />
        <dynamics damping="10.0" friction="50.0" />
    </joint>
    <!--************************************************LINK 6********************************************-->
    <link name="link6">
        <!--Link properties-->
        <visual>
            <origin rpy="0 0 0" xyz="0 0 0" />
            <geometry>
                <mesh filename="package://esercizio3_pkg/meshes/visual/link_6.dae" />
            </geometry>
            <material name="" />
        </visual>
        <collision>
            <origin rpy="0 0 0" xyz="0 0 0" />
            <geometry>
                <mesh filename="package://esercizio3_pkg/meshes/collision/link_6.stl" />
            </geometry>
        </collision>
        
<inertial>
            <mass value="0.1" />
            <inertia ixx="0.03" iyy="0.03" izz="0.03" ixy="0.0" ixz="0.0" iyz="0.0" />
        </inertial>

    </link>
    <joint name="joint6" type="revolute">
        <!--Joint properties-->
        <origin rpy="0 0 0" xyz="0 0 -0.15" />
        <parent link="link5" />
        <child link="link6" />
        <axis xyz="0 0 1" />
        <limit effort="5.8" lower="-6.28" upper="6.28" velocity="11.0" />
        <dynamics damping="10.0" friction="50.0" />
    </joint>
    <!--************************************************FLANGE********************************************-->
    <link name="flange" />
    <joint name="flange" type="fixed">
        <!--Joint properties-->
        <origin rpy="0 0 0" xyz="0 0 0" />
        <parent link="link6" />
        <child link="flange" />
    </joint>
    
<transmission name="trans_joint1">
        <type>transmission_interface/SimpleTransmission</type>
        <joint name="joint1">
            <hardwareInterface>hardware_interface/EffortJointInterface</hardwareInterface>
        </joint>
        <actuator name="joint1_motor">
            <hardwareInterface>hardware_interface/EffortJointInterface</hardwareInterface>
            <mechanicalReduction>1</mechanicalReduction>
        </actuator>
    </transmission>
    <transmission name="trans_joint2">
        <type>transmission_interface/SimpleTransmission</type>
        <joint name="joint2">
            <hardwareInterface>hardware_interface/EffortJointInterface</hardwareInterface>
        </joint>
        <actuator name="joint2_motor">
            <hardwareInterface>hardware_interface/EffortJointInterface</hardwareInterface>
            <mechanicalReduction>1</mechanicalReduction>
        </actuator>
    </transmission>
    <transmission name="trans_joint3">
        <type>transmission_interface/SimpleTransmission</type>
        <joint name="joint3">
            <hardwareInterface>hardware_interface/EffortJointInterface</hardwareInterface>
        </joint>
        <actuator name="joint3_motor">
            <hardwareInterface>hardware_interface/EffortJointInterface</hardwareInterface>
            <mechanicalReduction>1</mechanicalReduction>
        </actuator>
    </transmission>
    <transmission name="trans_joint4">
        <type>transmission_interface/SimpleTransmission</type>
        <joint name="joint4">
            <hardwareInterface>hardware_interface/EffortJointInterface</hardwareInterface>
        </joint>
        <actuator name="joint4_motor">
            <hardwareInterface>hardware_interface/EffortJointInterface</hardwareInterface>
            <mechanicalReduction>1</mechanicalReduction>
        </actuator>
    </transmission>
    <transmission name="trans_joint5">
        <type>transmission_interface/SimpleTransmission</type>
        <joint name="joint5">
            <hardwareInterface>hardware_interface/EffortJointInterface</hardwareInterface>
        </joint>
        <actuator name="joint5_motor">
            <hardwareInterface>hardware_interface/EffortJointInterface</hardwareInterface>
            <mechanicalReduction>1</mechanicalReduction>
        </actuator>
    </transmission>
    <transmission name="trans_joint6">
        <type>transmission_interface/SimpleTransmission</type>
        <joint name="joint6">
            <hardwareInterface>hardware_interface/EffortJointInterface</hardwareInterface>
        </joint>
        <actuator name="joint6_motor">
            <hardwareInterface>hardware_interface/EffortJointInterface</hardwareInterface>
            <mechanicalReduction>1</mechanicalReduction>
        </actuator>
    </transmission>
    <gazebo>
        <plugin name="gazebo_ros_control" filename="libgazebo_ros_control.so">
            <robotNamespace>/</robotNamespace>
        </plugin>
    </gazebo>
</robot>
